Traceback (most recent call last):
  File "server.py", line 7, in <module>
    mysql = MySQLConnector(app, 'mydb')
  File "/Users/coreyjjcunningham/Desktop/Python/flask_w_sql/db_connec/mysqlconnection.py", line 40, in MySQLConnector
    return MySQLConnection(app, db)
  File "/Users/coreyjjcunningham/Desktop/Python/flask_w_sql/db_connec/mysqlconnection.py", line 15, in __init__
    DATABASE_URI = "mysql://{}:{}@127.0.0.1:{}/{}".format(config['user'], config['password'], config['port'], config['database'])
KeyError: 'database'

1. No database in MySQLConnector object

sqlalchemy.exc.OperationalError: (_mysql_exceptions.OperationalError)
(1045, "Access denied for user 'rooter'@'localhost'
(using password: YES)") (Background on this error at: http://sqlalche.me/e/e3q8)

2. Wrong Username

super(Connection, self).__init__(*args, **kwargs2)
sqlalchemy.exc.OperationalError: (_mysql_exceptions.OperationalError)
 (1045, "Access denied for user 'root'@'localhost' (using password: YES)")
  (Background on this error at: http://sqlalche.me/e/e3q8)


3. Wrong password

sqlalchemy.exc.OperationalError: (_mysql_exceptions.OperationalError)
(2003, "Can't connect to MySQL server on '127.0.0.1' (61)") (
Background on this error at: http://sqlalche.me/e/e3q8)

4. Wrong Port

super(Connection, self).__init__(*args, **kwargs2)
sqlalchemy.exc.OperationalError: (_mysql_exceptions.OperationalError)
(2005, "Unknown MySQL server host 'shits' (0)")
(Background on this error at: http://sqlalche.me/e/e3q8)

5. Wrong Host 
